2024-04-11 15:55:02,966 - ERROR - root - Tour data not saved. Reason: No upcoming tours
2024-04-11 15:55:08,390 - INFO - root - Tour data saved successfully.
2024-04-11 15:55:10,084 - INFO - root - Email sent successfully.
2024-04-11 15:55:15,557 - ERROR - root - Tour data not saved. Reason: No upcoming tours
2024-04-11 15:55:20,883 - ERROR - root - Tour data not saved. Reason: No upcoming tours
2024-04-11 15:55:26,314 - ERROR - root - Tour data not saved. Reason: No upcoming tours
2024-04-11 15:55:31,735 - ERROR - root - Tour data not saved. Reason: No upcoming tours
2024-04-11 15:55:56,824 - INFO - root - Tour data saved successfully.
2024-04-11 15:55:58,087 - ERROR - root - Failed to send email: (535, b'5.7.8 Username and Password not accepted. For more information, go to\n5.7.8  https://support.google.com/mail/?p=BadCredentials r6-20020a05600c35c600b004163703fd6asm6377880wmq.1 - gsmtp')
Traceback (most recent call last):
  File "C:\Users\user\Documents\Database\Courses\Udemy\Ardit Sulce\1- Python Mega Course Learn Python in 60 Days\Projects\19- App 10 - Music Event Web Scraper\send_email.py", line 44, in send_email
    smtp_server.login(SENDER, PASSWORD)  # Login to the SMTP server
    ^^^^^^^^^^^^^^^^^^^^^^^^^^^^^^^^^^^
  File "C:\Users\user\AppData\Local\Programs\Python\Python312\Lib\smtplib.py", line 750, in login
    raise last_exception
  File "C:\Users\user\AppData\Local\Programs\Python\Python312\Lib\smtplib.py", line 739, in login
    (code, resp) = self.auth(
                   ^^^^^^^^^^
  File "C:\Users\user\AppData\Local\Programs\Python\Python312\Lib\smtplib.py", line 662, in auth
    raise SMTPAuthenticationError(code, resp)
smtplib.SMTPAuthenticationError: (535, b'5.7.8 Username and Password not accepted. For more information, go to\n5.7.8  https://support.google.com/mail/?p=BadCredentials r6-20020a05600c35c600b004163703fd6asm6377880wmq.1 - gsmtp')
2024-04-11 15:55:58,089 - ERROR - root - Failed to send email. Please try again later.
2024-04-11 15:56:03,474 - ERROR - root - Tour data not saved. Reason: Tour event already exists
2024-04-11 15:56:08,911 - ERROR - root - Tour data not saved. Reason: No upcoming tours
2024-04-11 15:56:14,343 - ERROR - root - Tour data not saved. Reason: No upcoming tours
2024-04-11 15:56:19,635 - ERROR - root - Tour data not saved. Reason: No upcoming tours
2024-04-11 15:56:25,094 - ERROR - root - Tour data not saved. Reason: No upcoming tours
2024-04-11 15:56:30,457 - ERROR - root - Tour data not saved. Reason: No upcoming tours
2024-04-11 15:56:35,856 - ERROR - root - Tour data not saved. Reason: No upcoming tours
2024-04-11 15:56:41,153 - ERROR - root - Tour data not saved. Reason: No upcoming tours
2024-04-11 15:56:46,593 - ERROR - root - Tour data not saved. Reason: No upcoming tours
2024-04-11 15:56:52,015 - ERROR - root - Tour data not saved. Reason: No upcoming tours
2024-04-11 15:56:57,445 - ERROR - root - Tour data not saved. Reason: Tour event already exists
2024-04-11 16:03:48,565 - ERROR - root - Tour data not saved. Reason: No upcoming tours
2024-04-11 16:03:51,888 - ERROR - root - Tour data not saved. Reason: No upcoming tours
2024-04-11 16:03:54,222 - ERROR - root - Tour data not saved. Reason: No upcoming tours
2024-04-11 16:03:56,517 - INFO - root - Tour data saved successfully.
2024-04-11 16:03:58,497 - INFO - root - Email sent successfully.
2024-04-11 16:04:00,805 - ERROR - root - Tour data not saved. Reason: No upcoming tours
2024-04-11 16:04:03,256 - ERROR - root - Tour data not saved. Reason: No upcoming tours
2024-04-11 16:04:26,293 - ERROR - root - An error occurred: HTTPConnectionPool(host='programmer100.pythonanywhere.com', port=80): Max retries exceeded with url: /tours/ (Caused by ConnectTimeoutError(<urllib3.connection.HTTPConnection object at 0x00000162281DC680>, 'Connection to programmer100.pythonanywhere.com timed out. (connect timeout=None)'))
2024-04-11 16:04:28,301 - ERROR - root - An error occurred: HTTPConnectionPool(host='programmer100.pythonanywhere.com', port=80): Max retries exceeded with url: /tours/ (Caused by NameResolutionError("<urllib3.connection.HTTPConnection object at 0x00000162281DCE00>: Failed to resolve 'programmer100.pythonanywhere.com' ([Errno 11001] getaddrinfo failed)"))
2024-04-11 16:04:30,309 - ERROR - root - An error occurred: HTTPConnectionPool(host='programmer100.pythonanywhere.com', port=80): Max retries exceeded with url: /tours/ (Caused by NameResolutionError("<urllib3.connection.HTTPConnection object at 0x00000162281DD6D0>: Failed to resolve 'programmer100.pythonanywhere.com' ([Errno 11001] getaddrinfo failed)"))
2024-04-11 16:04:32,318 - ERROR - root - An error occurred: HTTPConnectionPool(host='programmer100.pythonanywhere.com', port=80): Max retries exceeded with url: /tours/ (Caused by NameResolutionError("<urllib3.connection.HTTPConnection object at 0x00000162281DE000>: Failed to resolve 'programmer100.pythonanywhere.com' ([Errno 11001] getaddrinfo failed)"))
2024-04-11 16:04:34,328 - ERROR - root - An error occurred: HTTPConnectionPool(host='programmer100.pythonanywhere.com', port=80): Max retries exceeded with url: /tours/ (Caused by NameResolutionError("<urllib3.connection.HTTPConnection object at 0x00000162281DD520>: Failed to resolve 'programmer100.pythonanywhere.com' ([Errno 11001] getaddrinfo failed)"))
2024-04-11 16:04:36,337 - ERROR - root - An error occurred: HTTPConnectionPool(host='programmer100.pythonanywhere.com', port=80): Max retries exceeded with url: /tours/ (Caused by NameResolutionError("<urllib3.connection.HTTPConnection object at 0x00000162281DC620>: Failed to resolve 'programmer100.pythonanywhere.com' ([Errno 11001] getaddrinfo failed)"))
2024-04-11 16:04:38,342 - ERROR - root - An error occurred: HTTPConnectionPool(host='programmer100.pythonanywhere.com', port=80): Max retries exceeded with url: /tours/ (Caused by NameResolutionError("<urllib3.connection.HTTPConnection object at 0x00000162281DE1E0>: Failed to resolve 'programmer100.pythonanywhere.com' ([Errno 11001] getaddrinfo failed)"))
2024-04-11 16:04:40,350 - ERROR - root - An error occurred: HTTPConnectionPool(host='programmer100.pythonanywhere.com', port=80): Max retries exceeded with url: /tours/ (Caused by NameResolutionError("<urllib3.connection.HTTPConnection object at 0x00000162281DEB40>: Failed to resolve 'programmer100.pythonanywhere.com' ([Errno 11001] getaddrinfo failed)"))
2024-04-11 16:04:42,360 - ERROR - root - An error occurred: HTTPConnectionPool(host='programmer100.pythonanywhere.com', port=80): Max retries exceeded with url: /tours/ (Caused by NameResolutionError("<urllib3.connection.HTTPConnection object at 0x00000162281DF4D0>: Failed to resolve 'programmer100.pythonanywhere.com' ([Errno 11001] getaddrinfo failed)"))
2024-04-11 16:04:44,369 - ERROR - root - An error occurred: HTTPConnectionPool(host='programmer100.pythonanywhere.com', port=80): Max retries exceeded with url: /tours/ (Caused by NameResolutionError("<urllib3.connection.HTTPConnection object at 0x00000162281DFE60>: Failed to resolve 'programmer100.pythonanywhere.com' ([Errno 11001] getaddrinfo failed)"))
2024-04-11 16:04:46,381 - ERROR - root - An error occurred: HTTPConnectionPool(host='programmer100.pythonanywhere.com', port=80): Max retries exceeded with url: /tours/ (Caused by NameResolutionError("<urllib3.connection.HTTPConnection object at 0x00000162281DF2F0>: Failed to resolve 'programmer100.pythonanywhere.com' ([Errno 11001] getaddrinfo failed)"))
2024-04-11 16:04:48,391 - ERROR - root - An error occurred: HTTPConnectionPool(host='programmer100.pythonanywhere.com', port=80): Max retries exceeded with url: /tours/ (Caused by NameResolutionError("<urllib3.connection.HTTPConnection object at 0x00000162281DE960>: Failed to resolve 'programmer100.pythonanywhere.com' ([Errno 11001] getaddrinfo failed)"))
2024-04-11 16:04:50,399 - ERROR - root - An error occurred: HTTPConnectionPool(host='programmer100.pythonanywhere.com', port=80): Max retries exceeded with url: /tours/ (Caused by NameResolutionError("<urllib3.connection.HTTPConnection object at 0x00000162281DC3B0>: Failed to resolve 'programmer100.pythonanywhere.com' ([Errno 11001] getaddrinfo failed)"))
2024-04-11 16:04:52,409 - ERROR - root - An error occurred: HTTPConnectionPool(host='programmer100.pythonanywhere.com', port=80): Max retries exceeded with url: /tours/ (Caused by NameResolutionError("<urllib3.connection.HTTPConnection object at 0x00000162281DCDA0>: Failed to resolve 'programmer100.pythonanywhere.com' ([Errno 11001] getaddrinfo failed)"))
2024-04-11 16:04:54,418 - ERROR - root - An error occurred: HTTPConnectionPool(host='programmer100.pythonanywhere.com', port=80): Max retries exceeded with url: /tours/ (Caused by NameResolutionError("<urllib3.connection.HTTPConnection object at 0x00000162281DD250>: Failed to resolve 'programmer100.pythonanywhere.com' ([Errno 11001] getaddrinfo failed)"))
2024-04-11 16:04:56,430 - ERROR - root - An error occurred: HTTPConnectionPool(host='programmer100.pythonanywhere.com', port=80): Max retries exceeded with url: /tours/ (Caused by NameResolutionError("<urllib3.connection.HTTPConnection object at 0x00000162281FC8C0>: Failed to resolve 'programmer100.pythonanywhere.com' ([Errno 11001] getaddrinfo failed)"))
2024-04-11 16:04:58,439 - ERROR - root - An error occurred: HTTPConnectionPool(host='programmer100.pythonanywhere.com', port=80): Max retries exceeded with url: /tours/ (Caused by NameResolutionError("<urllib3.connection.HTTPConnection object at 0x00000162281DD520>: Failed to resolve 'programmer100.pythonanywhere.com' ([Errno 11001] getaddrinfo failed)"))
2024-04-11 16:05:00,449 - ERROR - root - An error occurred: HTTPConnectionPool(host='programmer100.pythonanywhere.com', port=80): Max retries exceeded with url: /tours/ (Caused by NameResolutionError("<urllib3.connection.HTTPConnection object at 0x00000162281DCF20>: Failed to resolve 'programmer100.pythonanywhere.com' ([Errno 11001] getaddrinfo failed)"))
2024-04-11 16:05:02,458 - ERROR - root - An error occurred: HTTPConnectionPool(host='programmer100.pythonanywhere.com', port=80): Max retries exceeded with url: /tours/ (Caused by NameResolutionError("<urllib3.connection.HTTPConnection object at 0x00000162281DC980>: Failed to resolve 'programmer100.pythonanywhere.com' ([Errno 11001] getaddrinfo failed)"))
2024-04-11 16:05:04,467 - ERROR - root - An error occurred: HTTPConnectionPool(host='programmer100.pythonanywhere.com', port=80): Max retries exceeded with url: /tours/ (Caused by NameResolutionError("<urllib3.connection.HTTPConnection object at 0x00000162281DEB70>: Failed to resolve 'programmer100.pythonanywhere.com' ([Errno 11001] getaddrinfo failed)"))
2024-04-11 16:05:06,471 - ERROR - root - An error occurred: HTTPConnectionPool(host='programmer100.pythonanywhere.com', port=80): Max retries exceeded with url: /tours/ (Caused by NameResolutionError("<urllib3.connection.HTTPConnection object at 0x00000162281DEDE0>: Failed to resolve 'programmer100.pythonanywhere.com' ([Errno 11001] getaddrinfo failed)"))
2024-04-11 16:06:31,826 - ERROR - root - Tour data not saved. Reason: No upcoming tours
2024-04-11 16:06:34,258 - ERROR - root - Tour data not saved. Reason: No upcoming tours
2024-04-11 16:06:36,605 - ERROR - root - Tour data not saved. Reason: No upcoming tours
2024-04-11 16:06:39,196 - INFO - root - Tour data saved successfully.
2024-04-11 16:06:41,015 - INFO - root - Email sent successfully.
2024-04-11 16:06:43,627 - ERROR - root - Tour data not saved. Reason: No upcoming tours
2024-04-11 16:06:45,976 - INFO - root - Tour data saved successfully.
2024-04-11 16:12:03,702 - ERROR - root - Tour data not saved. Reason: No upcoming tours
2024-04-11 16:12:06,018 - ERROR - root - Tour data not saved. Reason: No upcoming tours
2024-04-11 16:12:08,346 - ERROR - root - Tour data not saved. Reason: No upcoming tours
2024-04-11 16:12:31,384 - ERROR - root - An error occurred: HTTPConnectionPool(host='programmer100.pythonanywhere.com', port=80): Max retries exceeded with url: /tours/ (Caused by ConnectTimeoutError(<urllib3.connection.HTTPConnection object at 0x000002159AE21F70>, 'Connection to programmer100.pythonanywhere.com timed out. (connect timeout=None)'))
